<?xml version='1.0' encoding='utf-8'?>
<robot name="ASY__RIGHT_HAND_GEN1D_ON_FOREARM_GEN1D">
    <!--
    (c) 2025-2026 Proception Inc. All rights reserved.
    Licensed under the BSD 3-Clause License (full terms below); mesh geometry is licensed separately.

    BSD 3-Clause License

    Copyright (c) 2025-2026, Proception Inc.

    This license applies to this model file only. Mesh geometry (mesh files
    and any mesh geometry embedded in this file) is proprietary to Proception
    Inc. and licensed separately under the mesh geometry license terms.

    Redistribution and use in source and binary forms, with or without
    modification, are permitted provided that the following conditions are met:

    1. Redistributions of source code must retain the above copyright notice,
       this list of conditions and the following disclaimer.

    2. Redistributions in binary form must reproduce the above copyright
       notice, this list of conditions and the following disclaimer in the
       documentation and/or other materials provided with the distribution.

    3. Neither the name of the copyright holder nor the names of its
       contributors may be used to endorse or promote products derived from
       this software without specific prior written permission.

    THIS SOFTWARE IS PROVIDED BY THE COPYRIGHT HOLDERS AND CONTRIBUTORS
    "AS IS" AND ANY EXPRESS OR IMPLIED WARRANTIES, INCLUDING, BUT NOT LIMITED
    TO, THE IMPLIED WARRANTIES OF MERCHANTABILITY AND FITNESS FOR A PARTICULAR
    PURPOSE ARE DISCLAIMED. IN NO EVENT SHALL THE COPYRIGHT HOLDER OR
    CONTRIBUTORS BE LIABLE FOR ANY DIRECT, INDIRECT, INCIDENTAL, SPECIAL,
    EXEMPLARY, OR CONSEQUENTIAL DAMAGES (INCLUDING, BUT NOT LIMITED TO,
    PROCUREMENT OF SUBSTITUTE GOODS OR SERVICES; LOSS OF USE, DATA, OR
    PROFITS; OR BUSINESS INTERRUPTION) HOWEVER CAUSED AND ON ANY THEORY OF
    LIABILITY, WHETHER IN CONTRACT, STRICT LIABILITY, OR TORT (INCLUDING
    NEGLIGENCE OR OTHERWISE) ARISING IN ANY WAY OUT OF THE USE OF THIS
    SOFTWARE, EVEN IF ADVISED OF THE POSSIBILITY OF SUCH DAMAGE.

    For licensing inquiries, contact Proception Inc. at contact@proception.ai.
-->
    <!--
        ==================================================================================================================================
        |                                                      Generation Metadata                                                       |
        ==================================================================================================================================
        | Field           | Value                                                                                                        |
        ==================================================================================================================================
        | Generated on    | 2026-07-16 23:31:40 UTC                                                                                      |
        | Repository      | pro                                                                                                          |
        | Remote URL      | git@github.com:Proception-AI/pro                                                                             |
        | Branch          | user/jack/models/gen1D                                                                                       |
        | Commit          | 638b6efa6064                                                                                                 |
        | Generated by    | jack-proception                                                                                              |
        | Generator       | fusion2sim                                                                                                   |
        | Generator class | YamlRobot                                                                                                    |
        | Description     | (Post-processing (<class 'yrdf2sim.core.yaml_robot.YamlTree'>) based on YAML Robot Description Files [YRDF]) |
        ==================================================================================================================================
    -->
    <!-- Generated Body Links -->
    <link name="R_right_forearm_chs">
        <visual name="R_chs/visual">
            <geometry>
                <mesh filename="gen_1_D_R/optimized/asy_right_forearm_gen1d1_chassis_gen_1d1.obj" />
            </geometry>
        </visual>
        <collision name="R_chs/collision">
            <geometry>
                <mesh filename="gen_1_D_R/optimized/asy_right_forearm_gen1d1_chassis_gen_1d1.obj" />
            </geometry>
        </collision>
        <inertial>
            <mass value="5.7536239" />
            <origin xyz="-0.0000386 0.1070748 0.0191471" />
            <inertia ixx="2.022766e-02" iyy="4.968134e-03" izz="2.094171e-02" ixy="0.0" ixz="0.0" iyz="0.0" />
        </inertial>
    </link>
    <link name="R_right_forearm_bottom_virtual_cover1">
        <visual name="R_bottom_virtual_cover1/visual">
            <geometry>
                <mesh filename="gen_1_D_R/optimized/asy_right_forearm_gen1d1_bottom_virtual_cover1.obj" />
            </geometry>
        </visual>
        <collision name="R_bottom_virtual_cover1/collision">
            <geometry>
                <mesh filename="gen_1_D_R/optimized/asy_right_forearm_gen1d1_bottom_virtual_cover1.obj" />
            </geometry>
        </collision>
        <inertial>
            <mass value="0.0173193" />
            <origin xyz="0.0000000 0.0000000 0.0005000" />
            <inertia ixx="1.86024e-06" iyy="5.424478e-06" izz="7.281831e-06" ixy="0.0" ixz="0.0" iyz="0.0" />
        </inertial>
    </link>
    <link name="R_right_forearm_cover1">
        <visual name="R_virtual_cover1/visual">
            <geometry>
                <mesh filename="gen_1_D_R/optimized/asy_right_forearm_gen1d1_virtual_cover1.obj" />
            </geometry>
        </visual>
        <collision name="R_virtual_cover1/collision">
            <geometry>
                <mesh filename="gen_1_D_R/optimized/asy_right_forearm_gen1d1_virtual_cover1.obj" />
            </geometry>
        </collision>
        <inertial>
            <mass value="0.0462142" />
            <origin xyz="-0.0000007 0.2137000 0.0216575" />
            <inertia ixx="2.833063e-05" iyy="6.341319e-05" izz="3.509025e-05" ixy="0.0" ixz="0.0" iyz="0.0" />
        </inertial>
    </link>
    <link name="R_right_forearm_wrist_base">
        <visual name="R_wrist_base/visual">
            <geometry>
                <mesh filename="gen_1_D_R/optimized/asy_right_hand_gen1d1_sim_wrist_gen21_r1_base_gen211.obj" />
            </geometry>
        </visual>
        <collision name="R_wrist_base/collision">
            <geometry>
                <mesh filename="gen_1_D_R/optimized/asy_right_hand_gen1d1_sim_wrist_gen21_r1_base_gen211.obj" />
            </geometry>
        </collision>
        <inertial>
            <mass value="0.0249763" />
            <origin xyz="0.0000046 0.0061671 0.0004368" />
            <inertia ixx="5.728056e-06" iyy="1.163974e-05" izz="7.998322e-06" ixy="0.0" ixz="0.0" iyz="0.0" />
        </inertial>
    </link>
    <link name="R_right_forearm_wrist_ujoint">
        <visual name="R_wrist_ujoint/visual">
            <geometry>
                <mesh filename="gen_1_D_R/optimized/asy_right_hand_gen1d1_sim_wrist_gen21_r1_ujoint_gen211.obj" />
            </geometry>
        </visual>
        <collision name="R_wrist_ujoint/collision">
            <geometry>
                <mesh filename="gen_1_D_R/optimized/asy_right_hand_gen1d1_sim_wrist_gen21_r1_ujoint_gen211.obj" />
            </geometry>
        </collision>
        <inertial>
            <mass value="0.0512518" />
            <origin xyz="0.0124664 0.0000000 -0.0032079" />
            <inertia ixx="1.237338e-05" iyy="6.708757e-06" izz="1.103105e-05" ixy="0.0" ixz="0.0" iyz="0.0" />
        </inertial>
    </link>
    <link name="R_right_forearm_palm">
        <visual name="R_palm/visual">
            <geometry>
                <mesh filename="gen_1_D_R/optimized/asy_right_hand_gen1d1_palm_gen1b01.obj" />
            </geometry>
        </visual>
        <collision name="R_palm/collision">
            <geometry>
                <mesh filename="gen_1_D_R/optimized/asy_right_hand_gen1d1_palm_gen1b01.obj" />
            </geometry>
        </collision>
        <inertial>
            <mass value="0.1455486" />
            <origin xyz="-0.0003189 -0.0536559 -0.0027915" />
            <inertia ixx="1.970173e-04" iyy="8.125984e-05" izz="1.359965e-04" ixy="0.0" ixz="0.0" iyz="0.0" />
        </inertial>
    </link>
    <link name="R_right_forearm_gen1d01_meta">
        <visual name="R_gen1d01_meta/visual">
            <geometry>
                <mesh filename="gen_1_D_R/optimized/asy_right_hand_gen1d1_finger_gen1d01_metacarpal.obj" />
            </geometry>
        </visual>
        <collision name="R_gen1d01_meta/collision">
            <geometry>
                <mesh filename="gen_1_D_R/optimized/asy_right_hand_gen1d1_finger_gen1d01_metacarpal.obj" />
            </geometry>
        </collision>
        <inertial>
            <mass value="0.0043138" />
            <origin xyz="0.0000005 0.0024378 0.0002621" />
            <inertia ixx="1.669168e-07" iyy="1.661503e-07" izz="1.100527e-07" ixy="0.0" ixz="0.0" iyz="0.0" />
        </inertial>
    </link>
    <link name="R_right_forearm_gen1d01_prox">
        <visual name="R_gen1d01_prox/visual">
            <geometry>
                <mesh filename="gen_1_D_R/optimized/asy_right_hand_gen1d1_finger_gen1d01_proximal.obj" />
            </geometry>
        </visual>
        <collision name="R_gen1d01_prox/collision">
            <geometry>
                <mesh filename="gen_1_D_R/optimized/asy_right_hand_gen1d1_finger_gen1d01_proximal.obj" />
            </geometry>
        </collision>
        <inertial>
            <mass value="0.0107138" />
            <origin xyz="0.0020036 -0.0200417 0.0000000" />
            <inertia ixx="1.537877e-06" iyy="4.011074e-07" izz="1.416463e-06" ixy="0.0" ixz="0.0" iyz="0.0" />
        </inertial>
    </link>
    <link name="R_right_forearm_gen1d01_med">
        <visual name="R_gen1d01_med/visual">
            <geometry>
                <mesh filename="gen_1_D_R/optimized/asy_right_hand_gen1d1_finger_gen1d01_medial.obj" />
            </geometry>
        </visual>
        <collision name="R_gen1d01_med/collision">
            <geometry>
                <mesh filename="gen_1_D_R/optimized/asy_right_hand_gen1d1_finger_gen1d01_medial.obj" />
            </geometry>
        </collision>
        <inertial>
            <mass value="0.0053193" />
            <origin xyz="0.0017364 -0.0116914 -0.0000000" />
            <inertia ixx="3.546328e-07" iyy="1.970482e-07" izz="3.013907e-07" ixy="0.0" ixz="0.0" iyz="0.0" />
        </inertial>
    </link>
    <link name="R_right_forearm_gen1d01_dist">
        <visual name="R_gen1d01_dist/visual">
            <geometry>
                <mesh filename="gen_1_D_R/optimized/asy_right_hand_gen1d1_finger_gen1d01_distal.obj" />
            </geometry>
        </visual>
        <collision name="R_gen1d01_dist/collision">
            <geometry>
                <mesh filename="gen_1_D_R/optimized/asy_right_hand_gen1d1_finger_gen1d01_distal.obj" />
            </geometry>
        </collision>
        <inertial>
            <mass value="0.0062029" />
            <origin xyz="-0.0029017 -0.0133183 0.0000000" />
            <inertia ixx="4.271275e-07" iyy="1.726438e-07" izz="4.189138e-07" ixy="0.0" ixz="0.0" iyz="0.0" />
        </inertial>
    </link>
    <link name="R_right_forearm_gen1d02_meta">
        <visual name="R_gen1d02_meta/visual">
            <geometry>
                <mesh filename="gen_1_D_R/optimized/asy_right_hand_gen1d1_finger_gen1d02_metacarpal_gen1d01.obj" />
            </geometry>
        </visual>
        <collision name="R_gen1d02_meta/collision">
            <geometry>
                <mesh filename="gen_1_D_R/optimized/asy_right_hand_gen1d1_finger_gen1d02_metacarpal_gen1d01.obj" />
            </geometry>
        </collision>
        <inertial>
            <mass value="0.0043138" />
            <origin xyz="0.0000005 0.0024378 0.0002621" />
            <inertia ixx="1.669168e-07" iyy="1.661503e-07" izz="1.100527e-07" ixy="0.0" ixz="0.0" iyz="0.0" />
        </inertial>
    </link>
    <link name="R_right_forearm_gen1d02_prox">
        <visual name="R_gen1d02_prox/visual">
            <geometry>
                <mesh filename="gen_1_D_R/optimized/asy_right_hand_gen1d1_finger_gen1d02_proximal_gen1d01.obj" />
            </geometry>
        </visual>
        <collision name="R_gen1d02_prox/collision">
            <geometry>
                <mesh filename="gen_1_D_R/optimized/asy_right_hand_gen1d1_finger_gen1d02_proximal_gen1d01.obj" />
            </geometry>
        </collision>
        <inertial>
            <mass value="0.0107138" />
            <origin xyz="0.0020036 -0.0200417 0.0000000" />
            <inertia ixx="1.537877e-06" iyy="4.011074e-07" izz="1.416463e-06" ixy="0.0" ixz="0.0" iyz="0.0" />
        </inertial>
    </link>
    <link name="R_right_forearm_gen1d02_med">
        <visual name="R_gen1d02_med/visual">
            <geometry>
                <mesh filename="gen_1_D_R/optimized/asy_right_hand_gen1d1_finger_gen1d02_medial_gen1d01.obj" />
            </geometry>
        </visual>
        <collision name="R_gen1d02_med/collision">
            <geometry>
                <mesh filename="gen_1_D_R/optimized/asy_right_hand_gen1d1_finger_gen1d02_medial_gen1d01.obj" />
            </geometry>
        </collision>
        <inertial>
            <mass value="0.0053193" />
            <origin xyz="0.0017364 -0.0116914 -0.0000000" />
            <inertia ixx="3.546328e-07" iyy="1.970482e-07" izz="3.013907e-07" ixy="0.0" ixz="0.0" iyz="0.0" />
        </inertial>
    </link>
    <link name="R_right_forearm_gen1d02_dist">
        <visual name="R_gen1d02_dist/visual">
            <geometry>
                <mesh filename="gen_1_D_R/optimized/asy_right_hand_gen1d1_finger_gen1d02_distal_gen1d01.obj" />
            </geometry>
        </visual>
        <collision name="R_gen1d02_dist/collision">
            <geometry>
                <mesh filename="gen_1_D_R/optimized/asy_right_hand_gen1d1_finger_gen1d02_distal_gen1d01.obj" />
            </geometry>
        </collision>
        <inertial>
            <mass value="0.0062029" />
            <origin xyz="-0.0029017 -0.0133183 0.0000000" />
            <inertia ixx="4.271275e-07" iyy="1.726438e-07" izz="4.189138e-07" ixy="0.0" ixz="0.0" iyz="0.0" />
        </inertial>
    </link>
    <link name="R_right_forearm_meta">
        <visual name="R_gen1d03_meta/visual">
            <geometry>
                <mesh filename="gen_1_D_R/optimized/asy_right_hand_gen1d1_finger_gen1d03_metacarpal_gen1d01.obj" />
            </geometry>
        </visual>
        <collision name="R_gen1d03_meta/collision">
            <geometry>
                <mesh filename="gen_1_D_R/optimized/asy_right_hand_gen1d1_finger_gen1d03_metacarpal_gen1d01.obj" />
            </geometry>
        </collision>
        <inertial>
            <mass value="0.0043138" />
            <origin xyz="0.0000005 0.0024378 0.0002621" />
            <inertia ixx="1.669168e-07" iyy="1.661503e-07" izz="1.100527e-07" ixy="0.0" ixz="0.0" iyz="0.0" />
        </inertial>
    </link>
    <link name="R_right_forearm_prox">
        <visual name="R_gen1d03_prox/visual">
            <geometry>
                <mesh filename="gen_1_D_R/optimized/asy_right_hand_gen1d1_finger_gen1d03_proximal_gen1d01.obj" />
            </geometry>
        </visual>
        <collision name="R_gen1d03_prox/collision">
            <geometry>
                <mesh filename="gen_1_D_R/optimized/asy_right_hand_gen1d1_finger_gen1d03_proximal_gen1d01.obj" />
            </geometry>
        </collision>
        <inertial>
            <mass value="0.0107138" />
            <origin xyz="0.0020036 -0.0200417 0.0000000" />
            <inertia ixx="1.537877e-06" iyy="4.011074e-07" izz="1.416463e-06" ixy="0.0" ixz="0.0" iyz="0.0" />
        </inertial>
    </link>
    <link name="R_right_forearm_med">
        <visual name="R_gen1d03_med/visual">
            <geometry>
                <mesh filename="gen_1_D_R/optimized/asy_right_hand_gen1d1_finger_gen1d03_medial_gen1d01.obj" />
            </geometry>
        </visual>
        <collision name="R_gen1d03_med/collision">
            <geometry>
                <mesh filename="gen_1_D_R/optimized/asy_right_hand_gen1d1_finger_gen1d03_medial_gen1d01.obj" />
            </geometry>
        </collision>
        <inertial>
            <mass value="0.0053193" />
            <origin xyz="0.0017364 -0.0116914 -0.0000000" />
            <inertia ixx="3.546328e-07" iyy="1.970482e-07" izz="3.013907e-07" ixy="0.0" ixz="0.0" iyz="0.0" />
        </inertial>
    </link>
    <link name="R_right_forearm_dist">
        <visual name="R_gen1d03_dist/visual">
            <geometry>
                <mesh filename="gen_1_D_R/optimized/asy_right_hand_gen1d1_finger_gen1d03_distal_gen1d01.obj" />
            </geometry>
        </visual>
        <collision name="R_gen1d03_dist/collision">
            <geometry>
                <mesh filename="gen_1_D_R/optimized/asy_right_hand_gen1d1_finger_gen1d03_distal_gen1d01.obj" />
            </geometry>
        </collision>
        <inertial>
            <mass value="0.0062029" />
            <origin xyz="-0.0029017 -0.0133183 0.0000000" />
            <inertia ixx="4.271275e-07" iyy="1.726438e-07" izz="4.189138e-07" ixy="0.0" ixz="0.0" iyz="0.0" />
        </inertial>
    </link>
    <link name="R_right_forearm_pinky_meta">
        <visual name="R_pinky_meta/visual">
            <geometry>
                <mesh filename="gen_1_D_R/optimized/asy_right_hand_gen1d1_pinky_gen1d01_metacarpal_finger.obj" />
            </geometry>
        </visual>
        <collision name="R_pinky_meta/collision">
            <geometry>
                <mesh filename="gen_1_D_R/optimized/asy_right_hand_gen1d1_pinky_gen1d01_metacarpal_finger.obj" />
            </geometry>
        </collision>
        <inertial>
            <mass value="0.0043138" />
            <origin xyz="0.0000005 0.0024378 0.0002621" />
            <inertia ixx="1.669168e-07" iyy="1.661503e-07" izz="1.100527e-07" ixy="0.0" ixz="0.0" iyz="0.0" />
        </inertial>
    </link>
    <link name="R_right_forearm_pinky_prox">
        <visual name="R_pinky_prox/visual">
            <geometry>
                <mesh filename="gen_1_D_R/optimized/asy_right_hand_gen1d1_pinky_gen1d01_proximal.obj" />
            </geometry>
        </visual>
        <collision name="R_pinky_prox/collision">
            <geometry>
                <mesh filename="gen_1_D_R/optimized/asy_right_hand_gen1d1_pinky_gen1d01_proximal.obj" />
            </geometry>
        </collision>
        <inertial>
            <mass value="0.0076500" />
            <origin xyz="0.0018500 -0.0155669 -0.0000001" />
            <inertia ixx="7.286889e-07" iyy="2.804494e-07" izz="6.285112e-07" ixy="0.0" ixz="0.0" iyz="0.0" />
        </inertial>
    </link>
    <link name="R_right_forearm_pinky_med">
        <visual name="R_pinky_med/visual">
            <geometry>
                <mesh filename="gen_1_D_R/optimized/asy_right_hand_gen1d1_pinky_gen1d01_medial_finger.obj" />
            </geometry>
        </visual>
        <collision name="R_pinky_med/collision">
            <geometry>
                <mesh filename="gen_1_D_R/optimized/asy_right_hand_gen1d1_pinky_gen1d01_medial_finger.obj" />
            </geometry>
        </collision>
        <inertial>
            <mass value="0.0053193" />
            <origin xyz="0.0017364 -0.0116914 -0.0000000" />
            <inertia ixx="3.546328e-07" iyy="1.970482e-07" izz="3.013907e-07" ixy="0.0" ixz="0.0" iyz="0.0" />
        </inertial>
    </link>
    <link name="R_right_forearm_pinky_dist">
        <visual name="R_pinky_dist/visual">
            <geometry>
                <mesh filename="gen_1_D_R/optimized/asy_right_hand_gen1d1_pinky_gen1d01_distal_finger.obj" />
            </geometry>
        </visual>
        <collision name="R_pinky_dist/collision">
            <geometry>
                <mesh filename="gen_1_D_R/optimized/asy_right_hand_gen1d1_pinky_gen1d01_distal_finger.obj" />
            </geometry>
        </collision>
        <inertial>
            <mass value="0.0062029" />
            <origin xyz="-0.0029017 -0.0133183 0.0000000" />
            <inertia ixx="4.271275e-07" iyy="1.726438e-07" izz="4.189138e-07" ixy="0.0" ixz="0.0" iyz="0.0" />
        </inertial>
    </link>
    <link name="R_right_forearm_thumb_base">
        <visual name="R_thumb_base/visual">
            <geometry>
                <mesh filename="gen_1_D_R/optimized/asy_right_hand_gen1d1_thumb_gen1d01_base.obj" />
            </geometry>
        </visual>
        <collision name="R_thumb_base/collision">
            <geometry>
                <mesh filename="gen_1_D_R/optimized/asy_right_hand_gen1d1_thumb_gen1d01_base.obj" />
            </geometry>
        </collision>
        <inertial>
            <mass value="0.0070445" />
            <origin xyz="-0.0025202 0.0129502 -0.0053902" />
            <inertia ixx="1.263181e-06" iyy="4.813414e-07" izz="1.280585e-06" ixy="0.0" ixz="0.0" iyz="0.0" />
        </inertial>
    </link>
    <link name="R_right_forearm_thumb_trap">
        <visual name="R_thumb_trap/visual">
            <geometry>
                <mesh filename="gen_1_D_R/optimized/asy_right_hand_gen1d1_thumb_gen1d01_trapezium.obj" />
            </geometry>
        </visual>
        <collision name="R_thumb_trap/collision">
            <geometry>
                <mesh filename="gen_1_D_R/optimized/asy_right_hand_gen1d1_thumb_gen1d01_trapezium.obj" />
            </geometry>
        </collision>
        <inertial>
            <mass value="0.0081085" />
            <origin xyz="-0.0004402 -0.0025199 -0.0007116" />
            <inertia ixx="5.613289e-07" iyy="6.417263e-07" izz="4.19855e-07" ixy="0.0" ixz="0.0" iyz="0.0" />
        </inertial>
    </link>
    <link name="R_right_forearm_thumb_meta">
        <visual name="R_thumb_meta/visual">
            <geometry>
                <mesh filename="gen_1_D_R/optimized/asy_right_hand_gen1d1_thumb_gen1d01_metacarpal.obj" />
            </geometry>
        </visual>
        <collision name="R_thumb_meta/collision">
            <geometry>
                <mesh filename="gen_1_D_R/optimized/asy_right_hand_gen1d1_thumb_gen1d01_metacarpal.obj" />
            </geometry>
        </collision>
        <inertial>
            <mass value="0.0179407" />
            <origin xyz="0.0124978 -0.0008121 0.0024301" />
            <inertia ixx="1.77283e-06" iyy="2.210062e-06" izz="1.944541e-06" ixy="0.0" ixz="0.0" iyz="0.0" />
        </inertial>
    </link>
    <link name="R_right_forearm_thumb_prox">
        <visual name="R_thumb_prox/visual">
            <geometry>
                <mesh filename="gen_1_D_R/optimized/asy_right_hand_gen1d1_thumb_gen1d01_proximal.obj" />
            </geometry>
        </visual>
        <collision name="R_thumb_prox/collision">
            <geometry>
                <mesh filename="gen_1_D_R/optimized/asy_right_hand_gen1d1_thumb_gen1d01_proximal.obj" />
            </geometry>
        </collision>
        <inertial>
            <mass value="0.0124315" />
            <origin xyz="0.0001398 0.0158835 0.0001150" />
            <inertia ixx="1.572135e-06" iyy="6.250965e-07" izz="1.419345e-06" ixy="0.0" ixz="0.0" iyz="0.0" />
        </inertial>
    </link>
    <link name="R_right_forearm_thumb_dist">
        <visual name="R_thumb_dist/visual">
            <geometry>
                <mesh filename="gen_1_D_R/optimized/asy_right_hand_gen1d1_thumb_gen1d01_distal.obj" />
            </geometry>
        </visual>
        <collision name="R_thumb_dist/collision">
            <geometry>
                <mesh filename="gen_1_D_R/optimized/asy_right_hand_gen1d1_thumb_gen1d01_distal.obj" />
            </geometry>
        </collision>
        <inertial>
            <mass value="0.0115699" />
            <origin xyz="0.0002198 0.0155028 -0.0000000" />
            <inertia ixx="1.342975e-06" iyy="3.977205e-07" izz="1.294658e-06" ixy="0.0" ixz="0.0" iyz="0.0" />
        </inertial>
    </link>
    <!-- Generated Joints -->
    <joint type="fixed" name="R_ASY__RIGHT_HAND_GEN1D_ON_FOREARM_GEN1D/ASY__RIGHT_FOREARM_GEN1D1/Rigid_5">
        <parent link="R_right_forearm_chs" />
        <child link="R_right_forearm_bottom_virtual_cover1" />
        <origin xyz="0.0000000 0.0050000 0.0200000" rpy="-1.570796e+00 -1.15779e-15 -1.162841e-14" />
        <axis xyz="0 0 1" />
    </joint>
    <joint type="fixed" name="R_ASY__RIGHT_HAND_GEN1D_ON_FOREARM_GEN1D/ASY__RIGHT_FOREARM_GEN1D1/Rigid_4">
        <parent link="R_right_forearm_chs" />
        <child link="R_right_forearm_cover1" />
        <origin xyz="0.0000000 0.0120000 -0.0000000" rpy="-0e+00 -6.123e-17 0e+00" />
        <axis xyz="0 0 1" />
    </joint>
    <joint type="fixed" name="R_ASY__RIGHT_HAND_GEN1D_ON_FOREARM_GEN1D/Rigid_2">
        <parent link="R_right_forearm_chs" />
        <child link="R_right_forearm_wrist_base" />
        <origin xyz="0.0000000 0.2132000 0.0154500" rpy="1.5286e-16 6.144e-17 0e+00" />
        <axis xyz="0 0 1" />
    </joint>
    <joint type="revolute" name="R_wrist_abd">
        <parent link="R_right_forearm_wrist_base" />
        <child link="R_right_forearm_wrist_ujoint" />
        <origin xyz="-0.0000000 0.0200000 -0.0000000" rpy="-3.141593e+00 1.388e-17 1.570796e+00" />
        <axis xyz="0 0 1" />
        <limit lower="-5.235988e-01" upper="5.235988e-01" effort="0" velocity="0" />
    </joint>
    <joint type="revolute" name="R_wrist_flex">
        <parent link="R_right_forearm_wrist_ujoint" />
        <child link="R_right_forearm_palm" />
        <origin xyz="0.0180000 -0.0000000 -0.0050000" rpy="-1.570796e+00 1.570796e+00 0e+00" />
        <axis xyz="0 0 1" />
        <limit lower="-5.235988e-01" upper="1.134464e+00" effort="0" velocity="0" />
    </joint>
    <joint type="revolute" name="R_i0_CMC_abd">
        <parent link="R_right_forearm_palm" />
        <child link="R_right_forearm_gen1d01_meta" />
        <origin xyz="0.0010000 -0.0980000 0.0310000" rpy="3.141593e+00 1.570796e+00 0e+00" />
        <axis xyz="0 0 1" />
        <limit lower="-2.617994e-01" upper="5.235988e-01" effort="0" velocity="0" />
    </joint>
    <joint type="revolute" name="R_i1_MCP">
        <parent link="R_right_forearm_gen1d01_meta" />
        <child link="R_right_forearm_gen1d01_prox" />
        <origin xyz="-0.0000000 0.0069724 0.0000120" rpy="3.141593e+00 1.570796e+00 0e+00" />
        <axis xyz="0 0 1" />
        <limit lower="-3.490658e-01" upper="1.570796e+00" effort="0" velocity="0" />
    </joint>
    <joint type="revolute" name="R_i2_PIP">
        <parent link="R_right_forearm_gen1d01_prox" />
        <child link="R_right_forearm_gen1d01_med" />
        <origin xyz="0.0000000 -0.0420000 -0.0000000" rpy="9.1691e-16 -9.4369e-16 5.2311e-16" />
        <axis xyz="0 0 1" />
        <limit lower="-3.490658e-01" upper="1.570796e+00" effort="0" velocity="0" />
    </joint>
    <joint type="revolute" name="R_i3_DIP">
        <parent link="R_right_forearm_gen1d01_med" />
        <child link="R_right_forearm_gen1d01_dist" />
        <origin xyz="0.0040000 -0.0200000 0.0000000" rpy="-1.00602e-15 2.2204e-16 -1.6813e-16" />
        <axis xyz="0 0 1" />
        <limit lower="0e+00" upper="1.570796e+00" effort="0" velocity="0" />
    </joint>
    <joint type="revolute" name="R_m0_CMC_abd">
        <parent link="R_right_forearm_palm" />
        <child link="R_right_forearm_gen1d02_meta" />
        <origin xyz="0.0010000 -0.1080000 0.0100000" rpy="3.141593e+00 1.570796e+00 0e+00" />
        <axis xyz="0 0 1" />
        <limit lower="-2.617994e-01" upper="2.617994e-01" effort="0" velocity="0" />
    </joint>
    <joint type="revolute" name="R_m1_MCP">
        <parent link="R_right_forearm_gen1d02_meta" />
        <child link="R_right_forearm_gen1d02_prox" />
        <origin xyz="-0.0000000 0.0069724 0.0000120" rpy="3.141593e+00 1.570796e+00 0e+00" />
        <axis xyz="0 0 1" />
        <limit lower="-3.490658e-01" upper="1.570796e+00" effort="0" velocity="0" />
    </joint>
    <joint type="revolute" name="R_m2_PIP">
        <parent link="R_right_forearm_gen1d02_prox" />
        <child link="R_right_forearm_gen1d02_med" />
        <origin xyz="0.0000000 -0.0420000 -0.0000000" rpy="9.1691e-16 -9.4369e-16 5.2311e-16" />
        <axis xyz="0 0 1" />
        <limit lower="-3.490658e-01" upper="1.570796e+00" effort="0" velocity="0" />
    </joint>
    <joint type="revolute" name="R_m3_DIP">
        <parent link="R_right_forearm_gen1d02_med" />
        <child link="R_right_forearm_gen1d02_dist" />
        <origin xyz="0.0040000 -0.0200000 0.0000000" rpy="-1.00602e-15 2.2204e-16 -1.6813e-16" />
        <axis xyz="0 0 1" />
        <limit lower="0e+00" upper="1.570796e+00" effort="0" velocity="0" />
    </joint>
    <joint type="revolute" name="R_r0_CMC_abd">
        <parent link="R_right_forearm_palm" />
        <child link="R_right_forearm_meta" />
        <origin xyz="0.0010000 -0.0980000 -0.0110000" rpy="3.141593e+00 1.570796e+00 0e+00" />
        <axis xyz="0 0 1" />
        <limit lower="-2.617994e-01" upper="2.617994e-01" effort="0" velocity="0" />
    </joint>
    <joint type="revolute" name="R_r1_MCP">
        <parent link="R_right_forearm_meta" />
        <child link="R_right_forearm_prox" />
        <origin xyz="0.0000000 0.0069724 0.0000120" rpy="3.141593e+00 1.570796e+00 0e+00" />
        <axis xyz="0 0 1" />
        <limit lower="-3.490658e-01" upper="1.570796e+00" effort="0" velocity="0" />
    </joint>
    <joint type="revolute" name="R_r2_PIP">
        <parent link="R_right_forearm_prox" />
        <child link="R_right_forearm_med" />
        <origin xyz="0.0000000 -0.0420000 -0.0000000" rpy="9.1691e-16 -9.4369e-16 5.2311e-16" />
        <axis xyz="0 0 1" />
        <limit lower="-3.490658e-01" upper="1.570796e+00" effort="0" velocity="0" />
    </joint>
    <joint type="revolute" name="R_r3_DIP">
        <parent link="R_right_forearm_med" />
        <child link="R_right_forearm_dist" />
        <origin xyz="0.0040000 -0.0200000 0.0000000" rpy="-1.00602e-15 2.2204e-16 -1.6813e-16" />
        <axis xyz="0 0 1" />
        <limit lower="0e+00" upper="1.570796e+00" effort="0" velocity="0" />
    </joint>
    <joint type="revolute" name="R_p0_CMC_abd">
        <parent link="R_right_forearm_palm" />
        <child link="R_right_forearm_pinky_meta" />
        <origin xyz="0.0010000 -0.0930000 -0.0320000" rpy="3.141593e+00 1.570796e+00 0e+00" />
        <axis xyz="0 0 1" />
        <limit lower="-6.108652e-01" upper="2.617994e-01" effort="0" velocity="0" />
    </joint>
    <joint type="revolute" name="R_p1_MCP">
        <parent link="R_right_forearm_pinky_meta" />
        <child link="R_right_forearm_pinky_prox" />
        <origin xyz="0.0000000 0.0069724 0.0000120" rpy="3.141593e+00 1.570796e+00 0e+00" />
        <axis xyz="0 0 1" />
        <limit lower="-3.490658e-01" upper="1.570796e+00" effort="0" velocity="0" />
    </joint>
    <joint type="revolute" name="R_p2_PIP">
        <parent link="R_right_forearm_pinky_prox" />
        <child link="R_right_forearm_pinky_med" />
        <origin xyz="0.0000000 -0.0320000 -0.0000000" rpy="9.5985e-16 -9.4369e-16 5.2311e-16" />
        <axis xyz="0 0 1" />
        <limit lower="-3.490658e-01" upper="1.570796e+00" effort="0" velocity="0" />
    </joint>
    <joint type="revolute" name="R_p3_DIP">
        <parent link="R_right_forearm_pinky_med" />
        <child link="R_right_forearm_pinky_dist" />
        <origin xyz="0.0040000 -0.0200000 0.0000000" rpy="-1.04896e-15 -0e+00 -1.6813e-16" />
        <axis xyz="0 0 1" />
        <limit lower="0e+00" upper="1.570796e+00" effort="0" velocity="0" />
    </joint>
    <joint type="fixed" name="R_ASY__RIGHT_HAND_GEN1D_ON_FOREARM_GEN1D/ASY__RIGHT_HAND_GEN1D1/Rigid_2">
        <parent link="R_right_forearm_palm" />
        <child link="R_right_forearm_thumb_base" />
        <origin xyz="-0.0040000 -0.0272638 0.0199825" rpy="3.141593e+00 1.570796e+00 0e+00" />
        <axis xyz="0 0 1" />
    </joint>
    <joint type="revolute" name="R_t0_TM_abd">
        <parent link="R_right_forearm_thumb_base" />
        <child link="R_right_forearm_thumb_trap" />
        <origin xyz="-0.0035941 0.0122416 -0.0140000" rpy="1.919862e+00 1.570796e+00 0e+00" />
        <axis xyz="0 0 1" />
        <limit lower="0e+00" upper="2.094395e+00" effort="0" velocity="0" />
    </joint>
    <joint type="revolute" name="R_t1_TM">
        <parent link="R_right_forearm_thumb_trap" />
        <child link="R_right_forearm_thumb_meta" />
        <origin xyz="-0.0000000 -0.0100000 0.0010000" rpy="-1.570796e+00 3.8858e-16 -1.570796e+00" />
        <axis xyz="0 0 1" />
        <limit lower="-5.235988e-01" upper="1.047198e+00" effort="0" velocity="0" />
    </joint>
    <joint type="revolute" name="R_t2_MCP">
        <parent link="R_right_forearm_thumb_meta" />
        <child link="R_right_forearm_thumb_prox" />
        <origin xyz="0.0250000 -0.0000000 -0.0000000" rpy="-4.05159e-15 2.617994e-01 -1.570796e+00" />
        <axis xyz="0 0 1" />
        <limit lower="-3.490658e-01" upper="1.570796e+00" effort="0" velocity="0" />
    </joint>
    <joint type="revolute" name="R_t3_DIP">
        <parent link="R_right_forearm_thumb_prox" />
        <child link="R_right_forearm_thumb_dist" />
        <origin xyz="0.0000000 0.0320000 -0.0000000" rpy="-1.89576e-15 2.1233e-15 -2.05391e-15" />
        <axis xyz="0 0 1" />
        <limit lower="-3.490658e-01" upper="1.570796e+00" effort="0" velocity="0" />
    </joint>
</robot>